[2024-10-29T11:40:01.617585+0530] [0:00:00.393819] [script.py: 28] > starting script
[2024-10-29T11:40:02.557776+0530] [0:00:01.334010] [mail.py: 65] > Email has been sent successfully
[2024-10-29T11:40:02.557960+0530] [0:00:01.334194] [script.py: 43] > loading data
Traceback (most recent call last):
  File "/home/asyncxeno/Dev/price-monitoring/./script.py", line 55, in <module>
    driver = get_chromedriver_without_proxy()
  File "/home/asyncxeno/Dev/price-monitoring/utils/selenium_utils.py", line 16, in wrapper
    driver: uc.Chrome = f(*args, **kwargs)
  File "/home/asyncxeno/Dev/price-monitoring/utils/selenium_utils.py", line 53, in get_chromedriver_without_proxy
    driver = uc.Chrome(options=chrome_options, driver_executable_path=ChromeDriverManager().install())
  File "/home/asyncxeno/Dev/price-monitoring/venv/lib/python3.10/site-packages/undetected_chromedriver/__init__.py", line 466, in __init__
    super(Chrome, self).__init__(
  File "/home/asyncxeno/Dev/price-monitoring/venv/lib/python3.10/site-packages/selenium/webdriver/chrome/webdriver.py", line 45, in __init__
    super().__init__(
  File "/home/asyncxeno/Dev/price-monitoring/venv/lib/python3.10/site-packages/selenium/webdriver/chromium/webdriver.py", line 61, in __init__
    super().__init__(command_executor=executor, options=options)
  File "/home/asyncxeno/Dev/price-monitoring/venv/lib/python3.10/site-packages/selenium/webdriver/remote/webdriver.py", line 208, in __init__
    self.start_session(capabilities)
  File "/home/asyncxeno/Dev/price-monitoring/venv/lib/python3.10/site-packages/undetected_chromedriver/__init__.py", line 724, in start_session
    super(selenium.webdriver.chrome.webdriver.WebDriver, self).start_session(
  File "/home/asyncxeno/Dev/price-monitoring/venv/lib/python3.10/site-packages/selenium/webdriver/remote/webdriver.py", line 292, in start_session
    response = self.execute(Command.NEW_SESSION, caps)["value"]
  File "/home/asyncxeno/Dev/price-monitoring/venv/lib/python3.10/site-packages/selenium/webdriver/remote/webdriver.py", line 347, in execute
    self.error_handler.check_response(response)
  File "/home/asyncxeno/Dev/price-monitoring/venv/lib/python3.10/site-packages/selenium/webdriver/remote/errorhandler.py", line 229, in check_response
    raise exception_class(message, screen, stacktrace)
selenium.common.exceptions.SessionNotCreatedException: Message: session not created: cannot connect to chrome at 127.0.0.1:33007
from chrome not reachable
Stacktrace:
#0 0x57b497a5410a <unknown>
#1 0x57b49756f2bd <unknown>
#2 0x57b49755b4bf <unknown>
#3 0x57b4975aa56c <unknown>
#4 0x57b4975a0392 <unknown>
#5 0x57b4975ec156 <unknown>
#6 0x57b4975eb7a6 <unknown>
#7 0x57b4975dfdb3 <unknown>
#8 0x57b4975aec10 <unknown>
#9 0x57b4975afbee <unknown>
#10 0x57b497a2039b <unknown>
#11 0x57b497a24338 <unknown>
#12 0x57b497a0debc <unknown>
#13 0x57b497a24eb7 <unknown>
#14 0x57b4979f310f <unknown>
#15 0x57b497a42828 <unknown>
#16 0x57b497a429f0 <unknown>
#17 0x57b497a52f86 <unknown>
#18 0x701587494ac3 <unknown>

